No error handlers are registered, logging exception.
Traceback (most recent call last):
  File "/home/rasmus/openlink/venv/lib/python3.10/site-packages/telegram/ext/_application.py", line 1335, in process_update
    await coroutine
  File "/home/rasmus/openlink/venv/lib/python3.10/site-packages/telegram/ext/_handlers/basehandler.py", line 158, in handle_update
    return await self.callback(update, context)
  File "/home/rasmus/openlink/bot.py", line 63, in handle_message
    message_text = update.message.text
AttributeError: 'NoneType' object has no attribute 'text'
No error handlers are registered, logging exception.
Traceback (most recent call last):
  File "/home/rasmus/openlink/venv/lib/python3.10/site-packages/telegram/ext/_application.py", line 1335, in process_update
    await coroutine
  File "/home/rasmus/openlink/venv/lib/python3.10/site-packages/telegram/ext/_handlers/basehandler.py", line 158, in handle_update
    return await self.callback(update, context)
  File "/home/rasmus/openlink/bot.py", line 63, in handle_message
    message_text = update.message.text
AttributeError: 'NoneType' object has no attribute 'text'
No error handlers are registered, logging exception.
Traceback (most recent call last):
  File "/home/rasmus/openlink/venv/lib/python3.10/site-packages/telegram/ext/_application.py", line 1335, in process_update
    await coroutine
  File "/home/rasmus/openlink/venv/lib/python3.10/site-packages/telegram/ext/_handlers/basehandler.py", line 158, in handle_update
    return await self.callback(update, context)
  File "/home/rasmus/openlink/bot.py", line 63, in handle_message
    message_text = update.message.text
AttributeError: 'NoneType' object has no attribute 'text'
hey image: https://pbs.twimg.com/media/GY6KgAOa0AAsXmT?format=jpg&name=small
send?
reply None
hey image: https://pbs.twimg.com/media/GY_GOx_bAAMoE9k?format=jpg&name=small
send?
hey image: https://pbs.twimg.com/media/GY-A3YeXIAAnf10?format=jpg&name=small
send?
hey image: https://pbs.twimg.com/media/GY8LmdeXgAAHi9q?format=jpg&name=small
send?
hey image: https://pbs.twimg.com/media/GY65CS_bQAACXZ0?format=jpg&name=small
send?
reply Yapper No video support :(
Sending video: <coroutine object get_video_link at 0x7f7ae6d41a10>
sys:1: RuntimeWarning: coroutine 'get_video_link' was never awaited
RuntimeWarning: Enable tracemalloc to get the object allocation traceback
No error handlers are registered, logging exception.
Traceback (most recent call last):
  File "/home/rasmus/openlink/venv/lib/python3.10/site-packages/telegram/ext/_application.py", line 1335, in process_update
    await coroutine
  File "/home/rasmus/openlink/venv/lib/python3.10/site-packages/telegram/ext/_handlers/basehandler.py", line 158, in handle_update
    return await self.callback(update, context)
  File "/home/rasmus/openlink/bot.py", line 103, in handle_message
    message_text = update.message.text
AttributeError: 'NoneType' object has no attribute 'text'
No error handlers are registered, logging exception.
Traceback (most recent call last):
  File "/home/rasmus/openlink/venv/lib/python3.10/site-packages/telegram/ext/_application.py", line 1335, in process_update
    await coroutine
  File "/home/rasmus/openlink/venv/lib/python3.10/site-packages/telegram/ext/_handlers/basehandler.py", line 158, in handle_update
    return await self.callback(update, context)
  File "/home/rasmus/openlink/bot.py", line 103, in handle_message
    message_text = update.message.text
AttributeError: 'NoneType' object has no attribute 'text'
No error handlers are registered, logging exception.
Traceback (most recent call last):
  File "/home/rasmus/openlink/venv/lib/python3.10/site-packages/telegram/ext/_application.py", line 1335, in process_update
    await coroutine
  File "/home/rasmus/openlink/venv/lib/python3.10/site-packages/telegram/ext/_handlers/basehandler.py", line 158, in handle_update
    return await self.callback(update, context)
  File "/home/rasmus/openlink/bot.py", line 103, in handle_message
    message_text = update.message.text
AttributeError: 'NoneType' object has no attribute 'text'
No error handlers are registered, logging exception.
Traceback (most recent call last):
  File "/home/rasmus/openlink/venv/lib/python3.10/site-packages/telegram/ext/_application.py", line 1335, in process_update
    await coroutine
  File "/home/rasmus/openlink/venv/lib/python3.10/site-packages/telegram/ext/_handlers/basehandler.py", line 158, in handle_update
    return await self.callback(update, context)
  File "/home/rasmus/openlink/bot.py", line 103, in handle_message
    message_text = update.message.text
AttributeError: 'NoneType' object has no attribute 'text'
No error handlers are registered, logging exception.
Traceback (most recent call last):
  File "/home/rasmus/openlink/venv/lib/python3.10/site-packages/telegram/ext/_application.py", line 1335, in process_update
    await coroutine
  File "/home/rasmus/openlink/venv/lib/python3.10/site-packages/telegram/ext/_handlers/basehandler.py", line 158, in handle_update
    return await self.callback(update, context)
  File "/home/rasmus/openlink/bot.py", line 103, in handle_message
    message_text = update.message.text
AttributeError: 'NoneType' object has no attribute 'text'
No error handlers are registered, logging exception.
Traceback (most recent call last):
  File "/home/rasmus/openlink/venv/lib/python3.10/site-packages/telegram/ext/_updater.py", line 753, in _network_loop_retry
    if not await do_action():
  File "/home/rasmus/openlink/venv/lib/python3.10/site-packages/telegram/ext/_updater.py", line 747, in do_action
    return action_cb_task.result()
  File "/home/rasmus/openlink/venv/lib/python3.10/site-packages/telegram/ext/_updater.py", line 377, in polling_action_cb
    updates = await self.bot.get_updates(
  File "/home/rasmus/openlink/venv/lib/python3.10/site-packages/telegram/ext/_extbot.py", line 649, in get_updates
    updates = await super().get_updates(
  File "/home/rasmus/openlink/venv/lib/python3.10/site-packages/telegram/_bot.py", line 4366, in get_updates
    await self._post(
  File "/home/rasmus/openlink/venv/lib/python3.10/site-packages/telegram/_bot.py", line 623, in _post
    return await self._do_post(
  File "/home/rasmus/openlink/venv/lib/python3.10/site-packages/telegram/ext/_extbot.py", line 355, in _do_post
    return await super()._do_post(
  File "/home/rasmus/openlink/venv/lib/python3.10/site-packages/telegram/_bot.py", line 652, in _do_post
    result = await request.post(
  File "/home/rasmus/openlink/venv/lib/python3.10/site-packages/telegram/request/_baserequest.py", line 201, in post
    result = await self._request_wrapper(
  File "/home/rasmus/openlink/venv/lib/python3.10/site-packages/telegram/request/_baserequest.py", line 386, in _request_wrapper
    raise NetworkError(description or "Bad Gateway")
telegram.error.NetworkError: Bad Gateway
No error handlers are registered, logging exception.
Traceback (most recent call last):
  File "/home/rasmus/openlink/venv/lib/python3.10/site-packages/telegram/ext/_updater.py", line 753, in _network_loop_retry
    if not await do_action():
  File "/home/rasmus/openlink/venv/lib/python3.10/site-packages/telegram/ext/_updater.py", line 747, in do_action
    return action_cb_task.result()
  File "/home/rasmus/openlink/venv/lib/python3.10/site-packages/telegram/ext/_updater.py", line 377, in polling_action_cb
    updates = await self.bot.get_updates(
  File "/home/rasmus/openlink/venv/lib/python3.10/site-packages/telegram/ext/_extbot.py", line 649, in get_updates
    updates = await super().get_updates(
  File "/home/rasmus/openlink/venv/lib/python3.10/site-packages/telegram/_bot.py", line 4366, in get_updates
    await self._post(
  File "/home/rasmus/openlink/venv/lib/python3.10/site-packages/telegram/_bot.py", line 623, in _post
    return await self._do_post(
  File "/home/rasmus/openlink/venv/lib/python3.10/site-packages/telegram/ext/_extbot.py", line 355, in _do_post
    return await super()._do_post(
  File "/home/rasmus/openlink/venv/lib/python3.10/site-packages/telegram/_bot.py", line 652, in _do_post
    result = await request.post(
  File "/home/rasmus/openlink/venv/lib/python3.10/site-packages/telegram/request/_baserequest.py", line 201, in post
    result = await self._request_wrapper(
  File "/home/rasmus/openlink/venv/lib/python3.10/site-packages/telegram/request/_baserequest.py", line 386, in _request_wrapper
    raise NetworkError(description or "Bad Gateway")
telegram.error.NetworkError: Bad Gateway
No error handlers are registered, logging exception.
Traceback (most recent call last):
  File "/home/rasmus/openlink/venv/lib/python3.10/site-packages/telegram/ext/_updater.py", line 753, in _network_loop_retry
    if not await do_action():
  File "/home/rasmus/openlink/venv/lib/python3.10/site-packages/telegram/ext/_updater.py", line 747, in do_action
    return action_cb_task.result()
  File "/home/rasmus/openlink/venv/lib/python3.10/site-packages/telegram/ext/_updater.py", line 377, in polling_action_cb
    updates = await self.bot.get_updates(
  File "/home/rasmus/openlink/venv/lib/python3.10/site-packages/telegram/ext/_extbot.py", line 649, in get_updates
    updates = await super().get_updates(
  File "/home/rasmus/openlink/venv/lib/python3.10/site-packages/telegram/_bot.py", line 4366, in get_updates
    await self._post(
  File "/home/rasmus/openlink/venv/lib/python3.10/site-packages/telegram/_bot.py", line 623, in _post
    return await self._do_post(
  File "/home/rasmus/openlink/venv/lib/python3.10/site-packages/telegram/ext/_extbot.py", line 355, in _do_post
    return await super()._do_post(
  File "/home/rasmus/openlink/venv/lib/python3.10/site-packages/telegram/_bot.py", line 652, in _do_post
    result = await request.post(
  File "/home/rasmus/openlink/venv/lib/python3.10/site-packages/telegram/request/_baserequest.py", line 201, in post
    result = await self._request_wrapper(
  File "/home/rasmus/openlink/venv/lib/python3.10/site-packages/telegram/request/_baserequest.py", line 386, in _request_wrapper
    raise NetworkError(description or "Bad Gateway")
telegram.error.NetworkError: Bad Gateway
